[2024-06-17T00:17:47.897+0000] {local_task_job_runner.py:120} INFO - ::group::Pre task execution logs
[2024-06-17T00:17:47.930+0000] {taskinstance.py:2076} INFO - Dependencies all met for dep_context=non-requeueable deps ti=<TaskInstance: youtube_etl_dag.extract_data_from_youtube_api manual__2024-06-17T00:17:38.762733+00:00 [queued]>
[2024-06-17T00:17:47.942+0000] {taskinstance.py:2076} INFO - Dependencies all met for dep_context=requeueable deps ti=<TaskInstance: youtube_etl_dag.extract_data_from_youtube_api manual__2024-06-17T00:17:38.762733+00:00 [queued]>
[2024-06-17T00:17:47.944+0000] {taskinstance.py:2306} INFO - Starting attempt 1 of 2
[2024-06-17T00:17:47.992+0000] {taskinstance.py:2330} INFO - Executing <Task(PythonOperator): extract_data_from_youtube_api> on 2024-06-17 00:17:38.762733+00:00
[2024-06-17T00:17:47.999+0000] {standard_task_runner.py:90} INFO - Running: ['airflow', 'tasks', 'run', 'youtube_etl_dag', 'extract_data_from_youtube_api', 'manual__2024-06-17T00:17:38.762733+00:00', '--job-id', '4', '--raw', '--subdir', 'DAGS_FOLDER/youtube_etl_dag.py', '--cfg-path', '/tmp/tmpgwtej00p']
[2024-06-17T00:17:48.002+0000] {standard_task_runner.py:91} INFO - Job 4: Subtask extract_data_from_youtube_api
[2024-06-17T00:17:48.002+0000] {logging_mixin.py:188} WARNING - /home/airflow/.local/lib/python3.12/site-packages/airflow/task/task_runner/standard_task_runner.py:61 DeprecationWarning: This process (pid=416) is multi-threaded, use of fork() may lead to deadlocks in the child.
[2024-06-17T00:17:48.003+0000] {standard_task_runner.py:63} INFO - Started process 429 to run task
[2024-06-17T00:17:48.095+0000] {task_command.py:426} INFO - Running <TaskInstance: youtube_etl_dag.extract_data_from_youtube_api manual__2024-06-17T00:17:38.762733+00:00 [running]> on host 9ac4a088a2cc
[2024-06-17T00:17:48.241+0000] {taskinstance.py:2648} INFO - Exporting env vars: AIRFLOW_CTX_DAG_OWNER='airflow' AIRFLOW_CTX_DAG_ID='youtube_etl_dag' AIRFLOW_CTX_TASK_ID='extract_data_from_youtube_api' AIRFLOW_CTX_EXECUTION_DATE='2024-06-17T00:17:38.762733+00:00' AIRFLOW_CTX_TRY_NUMBER='1' AIRFLOW_CTX_DAG_RUN_ID='manual__2024-06-17T00:17:38.762733+00:00'
[2024-06-17T00:17:48.242+0000] {taskinstance.py:430} INFO - ::endgroup::
[2024-06-17T00:17:48.358+0000] {__init__.py:49} INFO - file_cache is only supported with oauth2client<4.0.0
[2024-06-17T00:17:48.366+0000] {_metadata.py:139} WARNING - Compute Engine Metadata server unavailable on attempt 1 of 3. Reason: [Errno 111] Connection refused
[2024-06-17T00:17:48.369+0000] {_metadata.py:139} WARNING - Compute Engine Metadata server unavailable on attempt 2 of 3. Reason: [Errno 111] Connection refused
[2024-06-17T00:17:48.373+0000] {_metadata.py:139} WARNING - Compute Engine Metadata server unavailable on attempt 3 of 3. Reason: [Errno 111] Connection refused
[2024-06-17T00:17:48.374+0000] {_default.py:338} WARNING - Authentication failed using Compute Engine authentication due to unavailable metadata server.
[2024-06-17T00:17:48.374+0000] {taskinstance.py:441} INFO - ::group::Post task execution logs
[2024-06-17T00:17:48.375+0000] {taskinstance.py:2905} ERROR - Task failed with exception
Traceback (most recent call last):
  File "/home/airflow/.local/lib/python3.12/site-packages/airflow/models/taskinstance.py", line 465, in _execute_task
    result = _execute_callable(context=context, **execute_callable_kwargs)
             ^^^^^^^^^^^^^^^^^^^^^^^^^^^^^^^^^^^^^^^^^^^^^^^^^^^^^^^^^^^^^
  File "/home/airflow/.local/lib/python3.12/site-packages/airflow/models/taskinstance.py", line 432, in _execute_callable
    return execute_callable(context=context, **execute_callable_kwargs)
           ^^^^^^^^^^^^^^^^^^^^^^^^^^^^^^^^^^^^^^^^^^^^^^^^^^^^^^^^^^^^
  File "/home/airflow/.local/lib/python3.12/site-packages/airflow/models/baseoperator.py", line 401, in wrapper
    return func(self, *args, **kwargs)
           ^^^^^^^^^^^^^^^^^^^^^^^^^^^
  File "/home/airflow/.local/lib/python3.12/site-packages/airflow/operators/python.py", line 235, in execute
    return_value = self.execute_callable()
                   ^^^^^^^^^^^^^^^^^^^^^^^
  File "/home/airflow/.local/lib/python3.12/site-packages/airflow/operators/python.py", line 252, in execute_callable
    return self.python_callable(*self.op_args, **self.op_kwargs)
           ^^^^^^^^^^^^^^^^^^^^^^^^^^^^^^^^^^^^^^^^^^^^^^^^^^^^^
  File "/opt/airflow/dags/youtube_etl_dag.py", line 42, in extract_data
    df_trending_videos = fetch_data_for_multiple_countries_and_categories(api_key, region_codes, category_ids)
                         ^^^^^^^^^^^^^^^^^^^^^^^^^^^^^^^^^^^^^^^^^^^^^^^^^^^^^^^^^^^^^^^^^^^^^^^^^^^^^^^^^^^^^
  File "/opt/airflow/dags/youtube_etl_dag.py", line 57, in fetch_data_for_multiple_countries_and_categories
    videos = fetch_trending_videos(api_key, region_code, category_id)
             ^^^^^^^^^^^^^^^^^^^^^^^^^^^^^^^^^^^^^^^^^^^^^^^^^^^^^^^^
  File "/opt/airflow/dags/youtube_etl_dag.py", line 80, in fetch_trending_videos
    youtube = build('youtube', 'v3', developerKey=api_key)
              ^^^^^^^^^^^^^^^^^^^^^^^^^^^^^^^^^^^^^^^^^^^^
  File "/home/airflow/.local/lib/python3.12/site-packages/googleapiclient/_helpers.py", line 130, in positional_wrapper
    return wrapped(*args, **kwargs)
           ^^^^^^^^^^^^^^^^^^^^^^^^
  File "/home/airflow/.local/lib/python3.12/site-packages/googleapiclient/discovery.py", line 315, in build
    service = build_from_document(
              ^^^^^^^^^^^^^^^^^^^^
  File "/home/airflow/.local/lib/python3.12/site-packages/googleapiclient/_helpers.py", line 130, in positional_wrapper
    return wrapped(*args, **kwargs)
           ^^^^^^^^^^^^^^^^^^^^^^^^
  File "/home/airflow/.local/lib/python3.12/site-packages/googleapiclient/discovery.py", line 616, in build_from_document
    credentials = _auth.default_credentials(
                  ^^^^^^^^^^^^^^^^^^^^^^^^^^
  File "/home/airflow/.local/lib/python3.12/site-packages/googleapiclient/_auth.py", line 57, in default_credentials
    credentials, _ = google.auth.default(
                     ^^^^^^^^^^^^^^^^^^^^
  File "/home/airflow/.local/lib/python3.12/site-packages/google/auth/_default.py", line 691, in default
    raise exceptions.DefaultCredentialsError(_CLOUD_SDK_MISSING_CREDENTIALS)
google.auth.exceptions.DefaultCredentialsError: Your default credentials were not found. To set up Application Default Credentials, see https://cloud.google.com/docs/authentication/external/set-up-adc for more information.
[2024-06-17T00:17:48.395+0000] {taskinstance.py:1206} INFO - Marking task as UP_FOR_RETRY. dag_id=youtube_etl_dag, task_id=extract_data_from_youtube_api, run_id=manual__2024-06-17T00:17:38.762733+00:00, execution_date=20240617T001738, start_date=20240617T001747, end_date=20240617T001748
[2024-06-17T00:17:48.439+0000] {standard_task_runner.py:110} ERROR - Failed to execute job 4 for task extract_data_from_youtube_api (Your default credentials were not found. To set up Application Default Credentials, see https://cloud.google.com/docs/authentication/external/set-up-adc for more information.; 429)
[2024-06-17T00:17:48.459+0000] {local_task_job_runner.py:240} INFO - Task exited with return code 1
[2024-06-17T00:17:48.494+0000] {taskinstance.py:3503} INFO - 0 downstream tasks scheduled from follow-on schedule check
[2024-06-17T00:17:48.497+0000] {local_task_job_runner.py:222} INFO - ::endgroup::
