[2024-06-17T23:52:41.824+0000] {local_task_job_runner.py:120} INFO - ::group::Pre task execution logs
[2024-06-17T23:52:41.867+0000] {taskinstance.py:2076} INFO - Dependencies all met for dep_context=non-requeueable deps ti=<TaskInstance: etl_dag.extract_data_from_youtube_api manual__2024-06-17T23:52:34.221451+00:00 [queued]>
[2024-06-17T23:52:41.885+0000] {taskinstance.py:2076} INFO - Dependencies all met for dep_context=requeueable deps ti=<TaskInstance: etl_dag.extract_data_from_youtube_api manual__2024-06-17T23:52:34.221451+00:00 [queued]>
[2024-06-17T23:52:41.887+0000] {taskinstance.py:2306} INFO - Starting attempt 1 of 2
[2024-06-17T23:52:41.934+0000] {taskinstance.py:2330} INFO - Executing <Task(PythonOperator): extract_data_from_youtube_api> on 2024-06-17 23:52:34.221451+00:00
[2024-06-17T23:52:41.941+0000] {standard_task_runner.py:90} INFO - Running: ['airflow', 'tasks', 'run', 'etl_dag', 'extract_data_from_youtube_api', 'manual__2024-06-17T23:52:34.221451+00:00', '--job-id', '71', '--raw', '--subdir', 'DAGS_FOLDER/etl.py', '--cfg-path', '/tmp/tmpz2_qwrzl']
[2024-06-17T23:52:41.944+0000] {standard_task_runner.py:91} INFO - Job 71: Subtask extract_data_from_youtube_api
[2024-06-17T23:52:41.946+0000] {logging_mixin.py:188} WARNING - /home/airflow/.local/lib/python3.12/site-packages/airflow/task/task_runner/standard_task_runner.py:61 DeprecationWarning: This process (pid=5418) is multi-threaded, use of fork() may lead to deadlocks in the child.
[2024-06-17T23:52:41.947+0000] {standard_task_runner.py:63} INFO - Started process 5431 to run task
[2024-06-17T23:52:42.110+0000] {task_command.py:426} INFO - Running <TaskInstance: etl_dag.extract_data_from_youtube_api manual__2024-06-17T23:52:34.221451+00:00 [running]> on host e1be22a1c874
[2024-06-17T23:52:42.400+0000] {taskinstance.py:2648} INFO - Exporting env vars: AIRFLOW_CTX_DAG_OWNER='airflow' AIRFLOW_CTX_DAG_ID='etl_dag' AIRFLOW_CTX_TASK_ID='extract_data_from_youtube_api' AIRFLOW_CTX_EXECUTION_DATE='2024-06-17T23:52:34.221451+00:00' AIRFLOW_CTX_TRY_NUMBER='1' AIRFLOW_CTX_DAG_RUN_ID='manual__2024-06-17T23:52:34.221451+00:00'
[2024-06-17T23:52:42.400+0000] {taskinstance.py:430} INFO - ::endgroup::
[2024-06-17T23:52:42.411+0000] {__init__.py:49} INFO - file_cache is only supported with oauth2client<4.0.0
[2024-06-17T23:52:42.418+0000] {_metadata.py:139} WARNING - Compute Engine Metadata server unavailable on attempt 1 of 3. Reason: [Errno 111] Connection refused
[2024-06-17T23:52:42.420+0000] {_metadata.py:139} WARNING - Compute Engine Metadata server unavailable on attempt 2 of 3. Reason: [Errno 111] Connection refused
[2024-06-17T23:52:42.422+0000] {_metadata.py:139} WARNING - Compute Engine Metadata server unavailable on attempt 3 of 3. Reason: [Errno 111] Connection refused
[2024-06-17T23:52:42.423+0000] {_default.py:338} WARNING - Authentication failed using Compute Engine authentication due to unavailable metadata server.
[2024-06-17T23:52:42.423+0000] {taskinstance.py:441} INFO - ::group::Post task execution logs
[2024-06-17T23:52:42.424+0000] {taskinstance.py:2905} ERROR - Task failed with exception
Traceback (most recent call last):
  File "/home/airflow/.local/lib/python3.12/site-packages/airflow/models/taskinstance.py", line 465, in _execute_task
    result = _execute_callable(context=context, **execute_callable_kwargs)
             ^^^^^^^^^^^^^^^^^^^^^^^^^^^^^^^^^^^^^^^^^^^^^^^^^^^^^^^^^^^^^
  File "/home/airflow/.local/lib/python3.12/site-packages/airflow/models/taskinstance.py", line 432, in _execute_callable
    return execute_callable(context=context, **execute_callable_kwargs)
           ^^^^^^^^^^^^^^^^^^^^^^^^^^^^^^^^^^^^^^^^^^^^^^^^^^^^^^^^^^^^
  File "/home/airflow/.local/lib/python3.12/site-packages/airflow/models/baseoperator.py", line 401, in wrapper
    return func(self, *args, **kwargs)
           ^^^^^^^^^^^^^^^^^^^^^^^^^^^
  File "/home/airflow/.local/lib/python3.12/site-packages/airflow/operators/python.py", line 235, in execute
    return_value = self.execute_callable()
                   ^^^^^^^^^^^^^^^^^^^^^^^
  File "/home/airflow/.local/lib/python3.12/site-packages/airflow/operators/python.py", line 252, in execute_callable
    return self.python_callable(*self.op_args, **self.op_kwargs)
           ^^^^^^^^^^^^^^^^^^^^^^^^^^^^^^^^^^^^^^^^^^^^^^^^^^^^^
  File "/opt/airflow/dags/etl.py", line 93, in extract_data
    df_trending_videos = fetch_data_for_multiple_countries_and_categories(api_key, region_codes, category_ids)
                         ^^^^^^^^^^^^^^^^^^^^^^^^^^^^^^^^^^^^^^^^^^^^^^^^^^^^^^^^^^^^^^^^^^^^^^^^^^^^^^^^^^^^^
  File "/opt/airflow/dags/etl.py", line 69, in fetch_data_for_multiple_countries_and_categories
    videos = fetch_trending_videos(api_key, region_code, category_id)
             ^^^^^^^^^^^^^^^^^^^^^^^^^^^^^^^^^^^^^^^^^^^^^^^^^^^^^^^^
  File "/opt/airflow/dags/etl.py", line 31, in fetch_trending_videos
    youtube = build('youtube', 'v3', developerKey=api_key)
              ^^^^^^^^^^^^^^^^^^^^^^^^^^^^^^^^^^^^^^^^^^^^
  File "/home/airflow/.local/lib/python3.12/site-packages/googleapiclient/_helpers.py", line 130, in positional_wrapper
    return wrapped(*args, **kwargs)
           ^^^^^^^^^^^^^^^^^^^^^^^^
  File "/home/airflow/.local/lib/python3.12/site-packages/googleapiclient/discovery.py", line 315, in build
    service = build_from_document(
              ^^^^^^^^^^^^^^^^^^^^
  File "/home/airflow/.local/lib/python3.12/site-packages/googleapiclient/_helpers.py", line 130, in positional_wrapper
    return wrapped(*args, **kwargs)
           ^^^^^^^^^^^^^^^^^^^^^^^^
  File "/home/airflow/.local/lib/python3.12/site-packages/googleapiclient/discovery.py", line 616, in build_from_document
    credentials = _auth.default_credentials(
                  ^^^^^^^^^^^^^^^^^^^^^^^^^^
  File "/home/airflow/.local/lib/python3.12/site-packages/googleapiclient/_auth.py", line 57, in default_credentials
    credentials, _ = google.auth.default(
                     ^^^^^^^^^^^^^^^^^^^^
  File "/home/airflow/.local/lib/python3.12/site-packages/google/auth/_default.py", line 691, in default
    raise exceptions.DefaultCredentialsError(_CLOUD_SDK_MISSING_CREDENTIALS)
google.auth.exceptions.DefaultCredentialsError: Your default credentials were not found. To set up Application Default Credentials, see https://cloud.google.com/docs/authentication/external/set-up-adc for more information.
[2024-06-17T23:52:42.442+0000] {taskinstance.py:1206} INFO - Marking task as UP_FOR_RETRY. dag_id=etl_dag, task_id=extract_data_from_youtube_api, run_id=manual__2024-06-17T23:52:34.221451+00:00, execution_date=20240617T235234, start_date=20240617T235241, end_date=20240617T235242
[2024-06-17T23:52:42.505+0000] {standard_task_runner.py:110} ERROR - Failed to execute job 71 for task extract_data_from_youtube_api (Your default credentials were not found. To set up Application Default Credentials, see https://cloud.google.com/docs/authentication/external/set-up-adc for more information.; 5431)
[2024-06-17T23:52:42.524+0000] {local_task_job_runner.py:240} INFO - Task exited with return code 1
[2024-06-17T23:52:42.554+0000] {taskinstance.py:3503} INFO - 0 downstream tasks scheduled from follow-on schedule check
[2024-06-17T23:52:42.556+0000] {local_task_job_runner.py:222} INFO - ::endgroup::
